Workbook
Name MRCodes: 'zPAMR Gen ID 40'!$D:$D
Name LMRCodes: zLMR!$A:$A
Name MRRates: 'zPAMR Gen ID 40'!$F:$F
Name DerivedCodes: zDerived!$A:$A
Name CostIndex: 'zCost Index'!$B$2:$B$16
Name District: 'zCost Index'!$A$2:$A$16
Name DerivedRates: zDerived!$D:$D
Name LMRRates: zLMR!$C:$C

Sheet GWD DR Abstract
A1: GWD Revised Derived Rates Based on DSR 21/PRICE (Gen ID 40) | J1: Select Distrct | L1: Index
J2: ADMIN | L2: {=((IFERROR(INDEX(CostIndex,MATCH(J2,District,0), ), )))} -> 1
A3: Sl No | B3: Code | C3: Item Name | D3: Item Name With Code | E3: Unit | F3: Main Category | G3: Sub Category 1 | H3: Sub Category 2 | I3: C1 | J3: C2 | K3: Indexed | L3: Total
A4: 1 | B4: GWDDR001 | C4: ='Well Protection'!A1 -> Well Protection Cover | D4: =CONCATENATE(C4," (Code: ",B4,")") -> Well Protection Cover (Code: GWDDR001) | E4: each | F4: GWD DR | G4: MWSS | H4: MWSS Accessories | I4: 0 | J4: ='Well Protection'!J30 -> 3800.0026 | K4: =J4*($L$2-1) -> 0 | L4: =SUM(I4:K4) -> 3800.0026
A5: 2 | B5: GWDDR002 | C5: ='Iron Structure'!A1 -> Angle Iron Structure To Support 5000 Litres Capacity Water Tank At 4 m Height | D5: =CONCATENATE(C5," (Code: ",B5,")") -> Angle Iron Structure To Support 5000 Litres Capacity Water Tank At 4 m Height (Code: GWDDR002) | E5: each | F5: GWD DR | G5: MWSS | H5: Iron Structure | I5: 0 | J5: ='Iron Structure'!J42 -> 71000.003 | K5: =J5*($L$2-1) -> 0 | L5: =SUM(I5:K5) -> 71000.003
A6: 3 | B6: GWDDR003 | C6: ='Iron Structure'!A44 -> Angle Iron Structure To Support 3000 Litres Capacity Water Tank At 4 m Height | D6: =CONCATENATE(C6," (Code: ",B6,")") -> Angle Iron Structure To Support 3000 Litres Capacity Water Tank At 4 m Height (Code: GWDDR003) | E6: each | F6: GWD DR | G6: MWSS | H6: Iron Structure | I6: 0 | J6: ='Iron Structure'!J85 -> 62000 | K6: =J6*($L$2-1) -> 0 | L6: =SUM(I6:K6) -> 62000
A7: 4 | B7: GWDDR004 | C7: ='Iron Structure'!A87 -> Angle Iron Structure To Support 5000 Litres Capacity Water Tank At 6 m Height | D7: =CONCATENATE(C7," (Code: ",B7,")") -> Angle Iron Structure To Support 5000 Litres Capacity Water Tank At 6 m Height (Code: GWDDR004) | E7: each | F7: GWD DR | G7: MWSS | H7: Iron Structure | I7: 0 | J7: ='Iron Structure'!J130 -> 93999.997 | K7: =J7*($L$2-1) -> 0 | L7: =SUM(I7:K7) -> 93999.997
A8: 5 | B8: GWDDR005 | C8: ='Iron Structure'!A132 -> Angle Iron Structure To Support 3000 Litres Capacity Water Tank At 6 m Height | D8: =CONCATENATE(C8," (Code: ",B8,")") -> Angle Iron Structure To Support 3000 Litres Capacity Water Tank At 6 m Height (Code: GWDDR005) | E8: each | F8: GWD DR | G8: MWSS | H8: Iron Structure | I8: 0 | J8: ='Iron Structure'!J175 -> 83000 | K8: =J8*($L$2-1) -> 0 | L8: =SUM(I8:K8) -> 83000
A9: 6 | B9: GWDDR006 | C9: ='Metallic PH'!A1 -> Metallic Pump House of size 1.2 x 0.9 x 2 m | D9: =CONCATENATE(C9," (Code: ",B9,")") -> Metallic Pump House of size 1.2 x 0.9 x 2 m (Code: GWDDR006) | E9: each | F9: GWD DR | G9: MWSS | H9: MWSS Accessories | I9: 0 | J9: ='Metallic PH'!J62 -> 25999.996 | K9: =J9*($L$2-1) -> 0 | L9: =SUM(I9:K9) -> 25999.996
A10: 7 | B10: GWDDR007 | C10: ='BW Casing Pipes'!B2 -> Supplying, assembling, lowering and fixing in vertical position in Borewell, PVC 140 mm 6 Kg/cm2 well casing pipe of required dia, conforming to IS : 4985:2000, including required hire and labour charges, fittings & accessories etc. all complete, for all depths, as per direction of Engineer- in- Charge. | D10: =CONCATENATE(C10," (Code: ",B10,")") -> Supplying, assembling, lowering and fixing in vertical position in Borewell, PVC 140 mm 6 Kg/cm2 well casing pipe of required dia, conforming to IS : 4985:2000, including required hire and labour charges, fittings & accessories etc. all complete, for all depths, as per direction of Engineer- in- Charge. (Code: GWDDR007) | E10: metre | F10: GWD DR | G10: Borewell | H10: PVC Casing Pipe (BW/FPW) | I10: ='BW Casing Pipes'!F13 -> 326.4 | J10: ='BW Casing Pipes'!F26 -> 11.2 | K10: =J10*($L$2-1) -> 0 | L10: =SUM(I10:K10) -> 337.6
A11: 8 | B11: GWDDR008 | C11: ='BW Casing Pipes'!B28 -> Supplying, assembling, lowering and fixing in vertical position in Borewell, PVC 140 mm 8 Kg/cm2 well casing pipe of required dia, conforming to IS : 4985:2000, including required hire and labour charges, fittings & accessories etc. all complete, for all depths, as per direction of Engineer- in- Charge. | D11: =CONCATENATE(C11," (Code: ",B11,")") -> Supplying, assembling, lowering and fixing in vertical position in Borewell, PVC 140 mm 8 Kg/cm2 well casing pipe of required dia, conforming to IS : 4985:2000, including required hire and labour charges, fittings & accessories etc. all complete, for all depths, as per direction of Engineer- in- Charge. (Code: GWDDR008) | E11: metre | F11: GWD DR | G11: Borewell | H11: PVC Casing Pipe (BW/FPW) | I11: ='BW Casing Pipes'!F39 -> 462.3 | J11: ='BW Casing Pipes'!F52 -> 11.2 | K11: =J11*($L$2-1) -> 0 | L11: =SUM(I11:K11) -> 473.5
A12: 9 | B12: GWDDR009 | C12: ='BW Casing Pipes'!B54 -> Supplying, assembling, lowering and fixing in vertical position in Borewell, PVC 160mm 6 Kg/cm2 well casing pipe of required dia, conforming to IS : 4985:2000, including required hire and labour charges, fittings & accessories etc. all complete, for all depths, as per direction of Engineer- in- Charge. | D12: =CONCATENATE(C12," (Code: ",B12,")") -> Supplying, assembling, lowering and fixing in vertical position in Borewell, PVC 160mm 6 Kg/cm2 well casing pipe of required dia, conforming to IS : 4985:2000, including required hire and labour charges, fittings & accessories etc. all complete, for all depths, as per direction of Engineer- in- Charge. (Code: GWDDR009) | E12: metre | F12: GWD DR | G12: Borewell | H12: PVC Casing Pipe (BW/FPW) | I12: ='BW Casing Pipes'!F65 -> 449.5 | J12: ='BW Casing Pipes'!F78 -> 11.2 | K12: =J12*($L$2-1) -> 0 | L12: =SUM(I12:K12) -> 460.7
A13: 10 | B13: GWDDR010 | C13: ='BW Casing Pipes'!B80 -> Supplying, assembling, lowering and fixing in vertical position in Borewell, PVC 180mm 6 Kg/cm2 well casing pipe of required dia, conforming to IS : 4985:2000, including required hire and labour charges, fittings & accessories etc. all complete, for all depths, as per direction of Engineer- in- Charge. | D13: =CONCATENATE(C13," (Code: ",B13,")") -> Supplying, assembling, lowering and fixing in vertical position in Borewell, PVC 180mm 6 Kg/cm2 well casing pipe of required dia, conforming to IS : 4985:2000, including required hire and labour charges, fittings & accessories etc. all complete, for all depths, as per direction of Engineer- in- Charge. (Code: GWDDR010) | E13: metre | F13: GWD DR | G13: Borewell | H13: PVC Casing Pipe (BW/FPW) | I13: ='BW Casing Pipes'!F91 -> 565.65 | J13: ='BW Casing Pipes'!F104 -> 11.2 | K13: =J13*($L$2-1) -> 0 | L13: =SUM(I13:K13) -> 576.85
A14: 11 | B14: GWDDR011 | C14: ='BW Casing Pipes'!B106 -> Supplying, assembling, lowering and fixing in vertical position in Borewell, PVC 180mm 8 Kg/cm2 well casing pipe of required dia, conforming to IS : 4985:2000, including required hire and labour charges, fittings & accessories etc. all complete, for all depths, as per direction of Engineer- in- Charge. | D14: =CONCATENATE(C14," (Code: ",B14,")") -> Supplying, assembling, lowering and fixing in vertical position in Borewell, PVC 180mm 8 Kg/cm2 well casing pipe of required dia, conforming to IS : 4985:2000, including required hire and labour charges, fittings & accessories etc. all complete, for all depths, as per direction of Engineer- in- Charge. (Code: GWDDR011) | E14: metre | F14: GWD DR | G14: Borewell | H14: PVC Casing Pipe (BW/FPW) | I14: ='BW Casing Pipes'!F117 -> 759.6 | J14: ='BW Casing Pipes'!F130 -> 11.2 | K14: =J14*($L$2-1) -> 0 | L14: =SUM(I14:K14) -> 770.8
A15: 12 | B15: GWDDR012 | C15: ='BW Casing Pipes'!B132 -> Supplying, assembling, lowering and fixing in vertical position in Borewell, PVC 200mm 8 Kg/cm2 well casing pipe of required dia, conforming to IS : 4985:2000, including required hire and labour charges, fittings & accessories etc. all complete, for all depths, as per direction of Engineer- in- Charge. | D15: =CONCATENATE(C15," (Code: ",B15,")") -> Supplying, assembling, lowering and fixing in vertical position in Borewell, PVC 200mm 8 Kg/cm2 well casing pipe of required dia, conforming to IS : 4985:2000, including required hire and labour charges, fittings & accessories etc. all complete, for all depths, as per direction of Engineer- in- Charge. (Code: GWDDR012) | E15: metre | F15: GWD DR | G15: Borewell | H15: PVC Casing Pipe (BW/FPW) | I15: ='BW Casing Pipes'!F143 -> 944.3 | J15: ='BW Casing Pipes'!F156 -> 11.2 | K15: =J15*($L$2-1) -> 0 | L15: =SUM(I15:K15) -> 955.5
A16: 13 | B16: GWDDR013 | C16: ='BW Casing Pipes'!B158 -> Supplying, assembling, lowering and fixing in vertical position in Borewell, PVC 200mm 10 Kg/cm2 well casing pipe of required dia, conforming to IS : 4985:2000, including required hire and labour charges, fittings & accessories etc. all complete, for all depths, as per direction of Engineer- in- Charge. | D16: =CONCATENATE(C16," (Code: ",B16,")") -> Supplying, assembling, lowering and fixing in vertical position in Borewell, PVC 200mm 10 Kg/cm2 well casing pipe of required dia, conforming to IS : 4985:2000, including required hire and labour charges, fittings & accessories etc. all complete, for all depths, as per direction of Engineer- in- Charge. (Code: GWDDR013) | E16: metre | F16: GWD DR | G16: Borewell | H16: PVC Casing Pipe (BW/FPW) | I16: ='BW Casing Pipes'!F169 -> 1111.55 | J16: ='BW Casing Pipes'!F182 -> 11.2 | K16: =J16*($L$2-1) -> 0 | L16: =SUM(I16:K16) -> 1122.75
A17: 14 | B17: GWDDR014 | C17: ='BW Casing Pipes'!B184 -> Supplying, assembling, lowering and fixing in vertical position in Borewell, PVC 110 mm 6 Kg/cm2 well casing pipe of required dia, conforming to IS : 4985:2000, including required hire and labour charges, fittings & accessories etc. all complete, for all depths, as per direction of Engineer- in- Charge. | D17: =CONCATENATE(C17," (Code: ",B17,")") -> Supplying, assembling, lowering and fixing in vertical position in Borewell, PVC 110 mm 6 Kg/cm2 well casing pipe of required dia, conforming to IS : 4985:2000, including required hire and labour charges, fittings & accessories etc. all complete, for all depths, as per direction of Engineer- in- Charge. (Code: GWDDR014) | E17: metre | F17: GWD DR | G17: Borewell | H17: PVC Casing Pipe (BW/FPW) | I17: ='BW Casing Pipes'!F195 -> 209.05 | J17: ='BW Casing Pipes'!F208 -> 11.2 | K17: =J17*($L$2-1) -> 0 | L17: =SUM(I17:K17) -> 220.25
A18: 15 | B18: GWDDR015 | C18: ='BW Casing Pipes'!B210 -> Supplying, assembling, lowering and fixing in vertical position in Borewell, PVC 110 mm 4 Kg/cm2 well casing pipe of required dia, conforming to IS : 4985:2000, including required hire and labour charges, fittings & accessories etc. all complete, for all depths, as per direction of Engineer- in- Charge. | D18: =CONCATENATE(C18," (Code: ",B18,")") -> Supplying, assembling, lowering and fixing in vertical position in Borewell, PVC 110 mm 4 Kg/cm2 well casing pipe of required dia, conforming to IS : 4985:2000, including required hire and labour charges, fittings & accessories etc. all complete, for all depths, as per direction of Engineer- in- Charge. (Code: GWDDR015) | E18: metre | F18: GWD DR | G18: Borewell | H18: PVC Casing Pipe (BW/FPW) | I18: ='BW Casing Pipes'!F221 -> 197.45 | J18: ='BW Casing Pipes'!F234 -> 11.2 | K18: =J18*($L$2-1) -> 0 | L18: =SUM(I18:K18) -> 208.65
A19: 16 | B19: GWDDR016 | C19: ='BW Casing Pipes'!B236 -> Supplying, assembling, lowering and fixing in vertical position in Borewell, PVC 140 mm 10 Kg/cm2 well casing pipe of required dia, conforming to IS : 4985:2000, including required hire and labour charges, fittings & accessories etc. all complete, for all depths, as per direction of Engineer- in- Charge. | D19: =CONCATENATE(C19," (Code: ",B19,")") -> Supplying, assembling, lowering and fixing in vertical position in Borewell, PVC 140 mm 10 Kg/cm2 well casing pipe of required dia, conforming to IS : 4985:2000, including required hire and labour charges, fittings & accessories etc. all complete, for all depths, as per direction of Engineer- in- Charge. (Code: GWDDR016) | E19: metre | F19: GWD DR | G19: Borewell | H19: PVC Casing Pipe (BW/FPW) | I19: ='BW Casing Pipes'!F247 -> 557.5 | J19: ='BW Casing Pipes'!F260 -> 11.2 | K19: =J19*($L$2-1) -> 0 | L19: =SUM(I19:K19) -> 568.7
A20: 17 | B20: GWDDR017 | C20: ='BW Casing Pipes'!B262 -> Supplying, assembling, lowering and fixing in vertical position in Borewell, PVC 180mm 10 Kg/cm2 well casing pipe of required dia, conforming to IS : 4985:2000, including required hire and labour charges, fittings & accessories etc. all complete, for all depths, as per direction of Engineer- in- Charge. | D20: =CONCATENATE(C20," (Code: ",B20,")") -> Supplying, assembling, lowering and fixing in vertical position in Borewell, PVC 180mm 10 Kg/cm2 well casing pipe of required dia, conforming to IS : 4985:2000, including required hire and labour charges, fittings & accessories etc. all complete, for all depths, as per direction of Engineer- in- Charge. (Code: GWDDR017) | E20: metre | F20: GWD DR | G20: Borewell | H20: PVC Casing Pipe (BW/FPW) | I20: ='BW Casing Pipes'!F273 -> 914.1 | J20: ='BW Casing Pipes'!F286 -> 11.2 | K20: =J20*($L$2-1) -> 0 | L20: =SUM(I20:K20) -> 925.3
A21: 18 | B21: GWDDR018 | C21: ='TW Casing Pipes'!B2 -> Supplying, assembling, lowering and fixing in vertical position in bore well, unplasticized PVC medium well casing (CM) pipe of required dia, conforming to IS : 12818, including required hire and labour charges, fittings & accessories etc. all complete, for all depths, as per direction of Engineer- in- Charge. 200 mm nominal size dia (23.3.3) | D21: =CONCATENATE(C21," (Code: ",B21,")") -> Supplying, assembling, lowering and fixing in vertical position in bore well, unplasticized PVC medium well casing (CM) pipe of required dia, conforming to IS : 12818, including required hire and labour charges, fittings & accessories etc. all complete, for all depths, as per direction of Engineer- in- Charge. 200 mm nominal size dia (23.3.3) (Code: GWDDR018) | E21: metre | F21: GWD DR | G21: Tubewell | H21: UPVC Casing Pipe (TW) | I21: 0 | J21: ='TW Casing Pipes'!C2 -> 826.44 | K21: =J21*($L$2-1) -> 0 | L21: =SUM(I21:K21) -> 826.44
A22: 19 | B22: GWDDR019 | C22: ='TW Casing Pipes'!B3 -> Supplying, assembling, lowering and fixing in vertical position in bore well unplasticized PVC medium well screen (RMS) pipes with ribs, conforming to IS: 12818, including hire & labour charges, fittings & accessories etc. all complete, for all depths, as per direction of Engineer - in-charge 200 mm nominal size dia (23.4.3) | D22: =CONCATENATE(C22," (Code: ",B22,")") -> Supplying, assembling, lowering and fixing in vertical position in bore well unplasticized PVC medium well screen (RMS) pipes with ribs, conforming to IS: 12818, including hire & labour charges, fittings & accessories etc. all complete, for all depths, as per direction of Engineer - in-charge 200 mm nominal size dia (23.4.3) (Code: GWDDR019) | E22: metre | F22: GWD DR | G22: Tubewell | H22: UPVC Casing Pipe (TW) | I22: 0 | J22: ='TW Casing Pipes'!C3 -> 954.28 | K22: =J22*($L$2-1) -> 0 | L22: =SUM(I22:K22) -> 954.28
A23: 20 | B23: GWDDR020 | C23: ='TW Casing Pipes'!B4 -> M.S. cap 200 mm dia (7748 - Water Charge and CPOH Added) | D23: =CONCATENATE(C23," (Code: ",B23,")") -> M.S. cap 200 mm dia (7748 - Water Charge and CPOH Added) (Code: GWDDR020) | E23: each | F23: GWD DR | G23: Tubewell | H23: Tubewell Fittings | I23: 0 | J23: ='TW Casing Pipes'!C4 -> 232.3 | K23: =J23*($L$2-1) -> 0 | L23: =SUM(I23:K23) -> 232.3
A24: 21 | B24: GWDDR021 | C24: ='TW Casing Pipes'!B5 -> Providing and fixing Bail plug / Bottom plug of required dia to the bottom of pipe assembly of tubewell as per IS : 2800 (part I). 200 mm dia (23.15.3) | D24: =CONCATENATE(C24," (Code: ",B24,")") -> Providing and fixing Bail plug / Bottom plug of required dia to the bottom of pipe assembly of tubewell as per IS : 2800 (part I). 200 mm dia (23.15.3) (Code: GWDDR021) | E24: each | F24: GWD DR | G24: Tubewell | H24: Tubewell Fittings | I24: 0 | J24: ='TW Casing Pipes'!C5 -> 267.85 | K24: =J24*($L$2-1) -> 0 | L24: =SUM(I24:K24) -> 267.85
A25: 22 | B25: GWDDR022 | C25: ='TW Casing Pipes'!B6 -> Supplying, assembling, lowering and fixing in vertical position in bore well, unplasticized PVC medium well casing (CM) pipe of required dia, conforming to IS : 12818, including required hire and labour charges, fittings & accessories etc. all complete, for all depths, as per direction of Engineer- in- Charge. 150 mm nominal size dia (23.3.2) | D25: =CONCATENATE(C25," (Code: ",B25,")") -> Supplying, assembling, lowering and fixing in vertical position in bore well, unplasticized PVC medium well casing (CM) pipe of required dia, conforming to IS : 12818, including required hire and labour charges, fittings & accessories etc. all complete, for all depths, as per direction of Engineer- in- Charge. 150 mm nominal size dia (23.3.2) (Code: GWDDR022) | E25: metre | F25: GWD DR | G25: Tubewell | H25: UPVC Casing Pipe (TW) | I25: 0 | J25: ='TW Casing Pipes'!C6 -> 580.35 | K25: =J25*($L$2-1) -> 0 | L25: =SUM(I25:K25) -> 580.35
A26: 23 | B26: GWDDR023 | C26: ='TW Casing Pipes'!B7 -> Supplying, assembling, lowering and fixing in vertical position in bore well unplasticized PVC medium well screen (RMS) pipes with ribs, conforming to IS: 12818, including hire & labour charges, fittings & accessories etc. all complete, for all depths, as per direction of Engineer - in-charge 150 mm nominal size dia (23.4.2) | D26: =CONCATENATE(C26," (Code: ",B26,")") -> Supplying, assembling, lowering and fixing in vertical position in bore well unplasticized PVC medium well screen (RMS) pipes with ribs, conforming to IS: 12818, including hire & labour charges, fittings & accessories etc. all complete, for all depths, as per direction of Engineer - in-charge 150 mm nominal size dia (23.4.2) (Code: GWDDR023) | E26: metre | F26: GWD DR | G26: Tubewell | H26: UPVC Casing Pipe (TW) | I26: 0 | J26: ='TW Casing Pipes'!C7 -> 591.96 | K26: =J26*($L$2-1) -> 0 | L26: =SUM(I26:K26) -> 591.96
A27: 24 | B27: GWDDR024 | C27: ='TW Casing Pipes'!B8 -> M.S. cap 150 mm dia (7747 - Water Charge and CPOH Added) | D27: =CONCATENATE(C27," (Code: ",B27,")") -> M.S. cap 150 mm dia (7747 - Water Charge and CPOH Added) (Code: GWDDR024) | E27: each | F27: GWD DR | G27: Tubewell | H27: Tubewell Fittings | I27: 0 | J27: ='TW Casing Pipes'!C8 -> 174.225 | K27: =J27*($L$2-1) -> 0 | L27: =SUM(I27:K27) -> 174.225
A28: 25 | B28: GWDDR025 | C28: ='TW Casing Pipes'!B9 -> Providing and fixing Bail plug / Bottom plug of required dia to the bottom of pipe assembly of tubewell as per IS : 2800 (part I). 150 mm dia (23.15.2) | D28: =CONCATENATE(C28," (Code: ",B28,")") -> Providing and fixing Bail plug / Bottom plug of required dia to the bottom of pipe assembly of tubewell as per IS : 2800 (part I). 150 mm dia (23.15.2) (Code: GWDDR025) | E28: each | F28: GWD DR | G28: Tubewell | H28: Tubewell Fittings | I28: 0 | J28: ='TW Casing Pipes'!C9 -> 244.62 | K28: =J28*($L$2-1) -> 0 | L28: =SUM(I28:K28) -> 244.62
A29: 26 | B29: GWDDR026 | C29: ='TW Casing Pipes'!B10 -> Supplying, assembling, lowering and fixing in vertical position in bore well, unplasticized PVC medium well casing (CM) pipe of required dia, conforming to IS : 12818, including required hire and labour charges, fittings & accessories etc. all complete, for all depths, as per direction of Engineer- in- Charge. 100 mm nominal size dia (23.3.1) | D29: =CONCATENATE(C29," (Code: ",B29,")") -> Supplying, assembling, lowering and fixing in vertical position in bore well, unplasticized PVC medium well casing (CM) pipe of required dia, conforming to IS : 12818, including required hire and labour charges, fittings & accessories etc. all complete, for all depths, as per direction of Engineer- in- Charge. 100 mm nominal size dia (23.3.1) (Code: GWDDR026) | E29: metre | F29: GWD DR | G29: Tubewell | H29: UPVC Casing Pipe (TW) | I29: 0 | J29: ='TW Casing Pipes'!C10 -> 480.23 | K29: =J29*($L$2-1) -> 0 | L29: =SUM(I29:K29) -> 480.23
A30: 27 | B30: GWDDR027 | C30: ='TW Casing Pipes'!B11 -> Supplying, assembling, lowering and fixing in vertical position in bore well unplasticized PVC medium well screen (RMS) pipes with ribs, conforming to IS: 12818, including hire & labour charges, fittings & accessories etc. all complete, for all depths, as per direction of Engineer - in-charge 100 mm nominal size dia (23.4.1) | D30: =CONCATENATE(C30," (Code: ",B30,")") -> Supplying, assembling, lowering and fixing in vertical position in bore well unplasticized PVC medium well screen (RMS) pipes with ribs, conforming to IS: 12818, including hire & labour charges, fittings & accessories etc. all complete, for all depths, as per direction of Engineer - in-charge 100 mm nominal size dia (23.4.1) (Code: GWDDR027) | E30: metre | F30: GWD DR | G30: Tubewell | H30: UPVC Casing Pipe (TW) | I30: 0 | J30: ='TW Casing Pipes'!C11 -> 503.46 | K30: =J30*($L$2-1) -> 0 | L30: =SUM(I30:K30) -> 503.46
A31: 28 | B31: GWDDR028 | C31: ='TW Casing Pipes'!B12 -> M.S. cap 100 mm dia (7760 - Water Charge and CPOH Added) | D31: =CONCATENATE(C31," (Code: ",B31,")") -> M.S. cap 100 mm dia (7760 - Water Charge and CPOH Added) (Code: GWDDR028) | E31: each | F31: GWD DR | G31: Tubewell | H31: Tubewell Fittings | I31: 0 | J31: ='TW Casing Pipes'!C12 -> 156.8025 | K31: =J31*($L$2-1) -> 0 | L31: =SUM(I31:K31) -> 156.8025
A32: 29 | B32: GWDDR029 | C32: ='TW Casing Pipes'!B13 -> Providing and fixing Bail plug / Bottom plug of required dia to the bottom of pipe assembly of tubewell as per IS : 2800 (part I). 100 mm dia (23.15.1) | D32: =CONCATENATE(C32," (Code: ",B32,")") -> Providing and fixing Bail plug / Bottom plug of required dia to the bottom of pipe assembly of tubewell as per IS : 2800 (part I). 100 mm dia (23.15.1) (Code: GWDDR029) | E32: each | F32: GWD DR | G32: Tubewell | H32: Tubewell Fittings | I32: 0 | J32: ='TW Casing Pipes'!C13 -> 198.15 | K32: =J32*($L$2-1) -> 0 | L32: =SUM(I32:K32) -> 198.15
A33: 30 | B33: GWDDR030 | C33: ='GI wo Trench'!B2 -> Providing and fixing G.I. pipes complete with G.I fittings: 25 mm dia nominal bore | D33: =CONCATENATE(C33," (Code: ",B33,")") -> Providing and fixing G.I. pipes complete with G.I fittings: 25 mm dia nominal bore (Code: GWDDR030) | E33: metre | F33: GWD DR | G33: MWSS | H33: GI Pipes Without Trenching | I33: 0 | J33: ='GI wo Trench'!F21 -> 263.95 | K33: =J33*($L$2-1) -> 0 | L33: =SUM(I33:K33) -> 263.95
A34: 31 | B34: GWDDR031 | C34: ='GI wo Trench'!B22 -> Providing and fixing G.I. pipes complete with G.I fittings: 32 mm dia nominal bore | D34: =CONCATENATE(C34," (Code: ",B34,")") -> Providing and fixing G.I. pipes complete with G.I fittings: 32 mm dia nominal bore (Code: GWDDR031) | E34: metre | F34: GWD DR | G34: MWSS | H34: GI Pipes Without Trenching | I34: 0 | J34: ='GI wo Trench'!F41 -> 298.45 | K34: =J34*($L$2-1) -> 0 | L34: =SUM(I34:K34) -> 298.45
A35: 32 | B35: GWDDR032 | C35: ='GI wo Trench'!B42 -> Providing and fixing G.I. pipes complete with G.I fittings: 40 mm dia nominal bore | D35: =CONCATENATE(C35," (Code: ",B35,")") -> Providing and fixing G.I. pipes complete with G.I fittings: 40 mm dia nominal bore (Code: GWDDR032) | E35: metre | F35: GWD DR | G35: MWSS | H35: GI Pipes Without Trenching | I35: 0 | J35: ='GI wo Trench'!F61 -> 385.85 | K35: =J35*($L$2-1) -> 0 | L35: =SUM(I35:K35) -> 385.85
A36: 33 | B36: GWDDR033 | C36: ='GI wo Trench'!B62 -> Providing and fixing G.I. pipes complete with G.I fittings: 50 mm dia nominal bore | D36: =CONCATENATE(C36," (Code: ",B36,")") -> Providing and fixing G.I. pipes complete with G.I fittings: 50 mm dia nominal bore (Code: GWDDR033) | E36: metre | F36: GWD DR | G36: MWSS | H36: GI Pipes Without Trenching | I36: 0 | J36: ='GI wo Trench'!F81 -> 469 | K36: =J36*($L$2-1) -> 0 | L36: =SUM(I36:K36) -> 469
A37: 34 | B37: GWDDR034 | C37: ='GI wo Trench'!B82 -> Providing and fixing G.I. pipes complete with G.I fittings: 65 mm dia nominal bore | D37: =CONCATENATE(C37," (Code: ",B37,")") -> Providing and fixing G.I. pipes complete with G.I fittings: 65 mm dia nominal bore (Code: GWDDR034) | E37: metre | F37: GWD DR | G37: MWSS | H37: GI Pipes Without Trenching | I37: 0 | J37: ='GI wo Trench'!F101 -> 568.35 | K37: =J37*($L$2-1) -> 0 | L37: =SUM(I37:K37) -> 568.35
A38: 35 | B38: GWDDR035 | C38: ='GI wo Trench'!B102 -> Providing and fixing G.I. pipes complete with G.I fittings: 80 mm dia nominal bore | D38: =CONCATENATE(C38," (Code: ",B38,")") -> Providing and fixing G.I. pipes complete with G.I fittings: 80 mm dia nominal bore (Code: GWDDR035) | E38: metre | F38: GWD DR | G38: MWSS | H38: GI Pipes Without Trenching | I38: 0 | J38: ='GI wo Trench'!F121 -> 699 | K38: =J38*($L$2-1) -> 0 | L38: =SUM(I38:K38) -> 699
A39: 36 | B39: GWDDR036 | C39: ='PVC wo Trench PRICE'!B24 -> Providing and fixing PVC pipes includes jointing of pipes with one step PVC solvent cement & testing of joints complete as per direction of Engineer in Charge. 25 mm dia 10KGF/cm2 | D39: =CONCATENATE(C39," (Code: ",B39,")") -> Providing and fixing PVC pipes includes jointing of pipes with one step PVC solvent cement & testing of joints complete as per direction of Engineer in Charge. 25 mm dia 10KGF/cm2 (Code: GWDDR036) | E39: metre | F39: GWD DR | G39: MWSS | H39: PVC Pipes Without Trenching | I39: ='PVC wo Trench PRICE'!F35 -> 64.11 | J39: ='PVC wo Trench PRICE'!F44 -> 29.66 | K39: =J39*($L$2-1) -> 0 | L39: =SUM(I39:K39) -> 93.77
A40: 37 | B40: GWDDR037 | C40: ='PVC wo Trench PRICE'!B46 -> Providing and fixing PVC pipes includes jointing of pipes with one step PVC solvent cement & testing of joints complete as per direction of Engineer in Charge. 32 mm dia 10KGF/cm2 | D40: =CONCATENATE(C40," (Code: ",B40,")") -> Providing and fixing PVC pipes includes jointing of pipes with one step PVC solvent cement & testing of joints complete as per direction of Engineer in Charge. 32 mm dia 10KGF/cm2 (Code: GWDDR037) | E40: metre | F40: GWD DR | G40: MWSS | H40: PVC Pipes Without Trenching | I40: ='PVC wo Trench PRICE'!F57 -> 86.82 | J40: ='PVC wo Trench PRICE'!F66 -> 29.66 | K40: =J40*($L$2-1) -> 0 | L40: =SUM(I40:K40) -> 116.48
...

Sheet GWD MR Abstract
A1: GWD Revised Market Rates Based on DSR 21/PRICE (Gen ID 40) | J1: Select Distrct | L1: Index
J2: ADMIN | L2: {=((IFERROR(INDEX(CostIndex,MATCH(J2,District,0), ), )))} -> 1
A3: Sl No | B3: Code | C3: Item Name | D3: Item Name With Code | E3: Unit | F3: Main Category | G3: Sub Category 1 | H3: Sub Category 2 | I3: C1 | J3: C2 | K3: Indexed | L3: Total
A4: 1 | B4: GWDMR001 | C4: S&F PVC Bend 90 mm (DG) | D4: =CONCATENATE(C4," (Code: ",B4,")") -> S&F PVC Bend 90 mm (DG) (Code: GWDMR001) | E4: each | F4: GWD MR | G4: PVC Fittings | H4: PVC Bend | I4: 80 | J4: 31 | K4: =J4*($L$2-1) -> 0 | L4: =SUM(I4:K4) -> 111
A5: 2 | B5: GWDMR002 | C5: S&F PVC Bend 140 mm (DG) | D5: =CONCATENATE(C5," (Code: ",B5,")") -> S&F PVC Bend 140 mm (DG) (Code: GWDMR002) | E5: each | F5: GWD MR | G5: PVC Fittings | H5: PVC Bend | I5: 150 | J5: 35 | K5: =J5*($L$2-1) -> 0 | L5: =SUM(I5:K5) -> 185
A6: 3 | B6: GWDMR003 | C6: PVC End cap 140 mm (DG) | D6: =CONCATENATE(C6," (Code: ",B6,")") -> PVC End cap 140 mm (DG) (Code: GWDMR003) | E6: each | F6: GWD MR | G6: PVC Fittings | H6: PVC End Cap | I6: 38.5 | J6: 37 | K6: =J6*($L$2-1) -> 0 | L6: =SUM(I6:K6) -> 75.5
A7: 4 | B7: GWDMR004 | C7: PVC End cap 150 mm (DG) | D7: =CONCATENATE(C7," (Code: ",B7,")") -> PVC End cap 150 mm (DG) (Code: GWDMR004) | E7: each | F7: GWD MR | G7: PVC Fittings | H7: PVC End Cap | I7: 41.2 | J7: 39.5 | K7: =J7*($L$2-1) -> 0 | L7: =SUM(I7:K7) -> 80.7
A8: 5 | B8: GWDMR005 | C8: PVC End Cap 180 mm (DG) | D8: =CONCATENATE(C8," (Code: ",B8,")") -> PVC End Cap 180 mm (DG) (Code: GWDMR005) | E8: each | F8: GWD MR | G8: PVC Fittings | H8: PVC End Cap | I8: 47.8 | J8: 44 | K8: =J8*($L$2-1) -> 0 | L8: =SUM(I8:K8) -> 91.8
A9: 6 | B9: GWDMR006 | C9: PVC End Cap 200 mm (DG) | D9: =CONCATENATE(C9," (Code: ",B9,")") -> PVC End Cap 200 mm (DG) (Code: GWDMR006) | E9: each | F9: GWD MR | G9: PVC Fittings | H9: PVC End Cap | I9: 52.5 | J9: 48.5 | K9: =J9*($L$2-1) -> 0 | L9: =SUM(I9:K9) -> 101
A10: 7 | B10: GWDMR007 | C10: PVC Square End Cap 140 mm | D10: =CONCATENATE(C10," (Code: ",B10,")") -> PVC Square End Cap 140 mm (Code: GWDMR007) | E10: each | F10: GWD MR | G10: ARS | H10: ARS Fittings | I10: 200 | J10: 0 | K10: =J10*($L$2-1) -> 0 | L10: =SUM(I10:K10) -> 200
A11: 8 | B11: GWDMR008 | C11: PVC Square End Cap 160 mm | D11: =CONCATENATE(C11," (Code: ",B11,")") -> PVC Square End Cap 160 mm (Code: GWDMR008) | E11: each | F11: GWD MR | G11: ARS | H11: ARS Fittings | I11: 250 | J11: 0 | K11: =J11*($L$2-1) -> 0 | L11: =SUM(I11:K11) -> 250
A12: 9 | B12: GWDMR009 | C12: PVC Half End Cap 140 mm | D12: =CONCATENATE(C12," (Code: ",B12,")") -> PVC Half End Cap 140 mm (Code: GWDMR009) | E12: each | F12: GWD MR | G12: ARS | H12: ARS Fittings | I12: 150 | J12: 0 | K12: =J12*($L$2-1) -> 0 | L12: =SUM(I12:K12) -> 150
A13: 10 | B13: GWDMR010 | C13: PVC Half End Cap 160 mm | D13: =CONCATENATE(C13," (Code: ",B13,")") -> PVC Half End Cap 160 mm (Code: GWDMR010) | E13: each | F13: GWD MR | G13: ARS | H13: ARS Fittings | I13: 160 | J13: 0 | K13: =J13*($L$2-1) -> 0 | L13: =SUM(I13:K13) -> 160
A14: 11 | B14: GWDMR011 | C14: PVC Half Square End Cap 140 mm | D14: =CONCATENATE(C14," (Code: ",B14,")") -> PVC Half Square End Cap 140 mm (Code: GWDMR011) | E14: each | F14: GWD MR | G14: ARS | H14: ARS Fittings | I14: 150 | J14: 0 | K14: =J14*($L$2-1) -> 0 | L14: =SUM(I14:K14) -> 150
A15: 12 | B15: GWDMR012 | C15: PVC Half Square End Cap 160 mm | D15: =CONCATENATE(C15," (Code: ",B15,")") -> PVC Half Square End Cap 160 mm (Code: GWDMR012) | E15: each | F15: GWD MR | G15: ARS | H15: ARS Fittings | I15: 175 | J15: 0 | K15: =J15*($L$2-1) -> 0 | L15: =SUM(I15:K15) -> 175
... A23: 20 | B23: GWDMR020 | C23: PVC Reducer 160X110 mm | D23: =CONCATENATE(C23," (Code: ",B23,")") -> PVC Reducer 160X110 mm (Code: GWDMR020) | E23: each | F23: GWD MR | G23: PVC Fittings | H23: PVC Reducer | I23: 290 | J23: 0 | K23: =J23*($L$2-1) -> 0 | L23: =SUM(I23:K23) -> 290
A24: 20A | B24: GWDMR020A | C24: PVC Reducer 140X110 mm | D24: =CONCATENATE(C24," (Code: ",B24,")") -> PVC Reducer 140X110 mm (Code: GWDMR020A) | E24: each | F24: GWD MR | G24: PVC Fittings | H24: PVC Reducer | I24: 196 | J24: 0 | K24: =J24*($L$2-1) -> 0 | L24: =SUM(I24:K24) -> 196
A25: 21 | B25: GWDMR021 | C25: PVC Runner Drop 140 mm | D25: =CONCATENATE(C25," (Code: ",B25,")") -> PVC Runner Drop 140 mm (Code: GWDMR021) | E25: each | F25: GWD MR | G25: ARS | H25: ARS Fittings | I25: 210 | J25: 0 | K25: =J25*($L$2-1) -> 0 | L25: =SUM(I25:K25) -> 210
A26: 22 | B26: GWDMR022 | C26: PVC Runner Drop 160 mm | D26: =CONCATENATE(C26," (Code: ",B26,")") -> PVC Runner Drop 160 mm (Code: GWDMR022) | E26: each | F26: GWD MR | G26: ARS | H26: ARS Fittings | I26: 240 | J26: 0 | K26: =J26*($L$2-1) -> 0 | L26: =SUM(I26:K26) -> 240
A27: 23 | B27: GWDMR023 | C27: PVC End Drop 140 mm | D27: =CONCATENATE(C27," (Code: ",B27,")") -> PVC End Drop 140 mm (Code: GWDMR023) | E27: each | F27: GWD MR | G27: ARS | H27: ARS Fittings | I27: 192 | J27: 0 | K27: =J27*($L$2-1) -> 0 | L27: =SUM(I27:K27) -> 192
A28: 24 | B28: GWDMR024 | C28: PVC End Drop 160 mm | D28: =CONCATENATE(C28," (Code: ",B28,")") -> PVC End Drop 160 mm (Code: GWDMR024) | E28: each | F28: GWD MR | G28: ARS | H28: ARS Fittings | I28: 216 | J28: 0 | K28: =J28*($L$2-1) -> 0 | L28: =SUM(I28:K28) -> 216
A29: 25 | B29: GWDMR025 | C29: PVC Half End Drop 140 mm | D29: =CONCATENATE(C29," (Code: ",B29,")") -> PVC Half End Drop 140 mm (Code: GWDMR025) | E29: each | F29: GWD MR | G29: ARS | H29: ARS Fittings | I29: 174 | J29: 0 | K29: =J29*($L$2-1) -> 0 | L29: =SUM(I29:K29) -> 174
A30: 26 | B30: GWDMR026 | C30: PVC Half End Drop 160 mm | D30: =CONCATENATE(C30," (Code: ",B30,")") -> PVC Half End Drop 160 mm (Code: GWDMR026) | E30: each | F30: GWD MR | G30: ARS | H30: ARS Fittings | I30: 192 | J30: 0 | K30: =J30*($L$2-1) -> 0 | L30: =SUM(I30:K30) -> 192
A31: 27 | B31: GWDMR027 | C31: PVC Square End Drop 140 mm | D31: =CONCATENATE(C31," (Code: ",B31,")") -> PVC Square End Drop 140 mm (Code: GWDMR027) | E31: each | F31: GWD MR | G31: ARS | H31: ARS Fittings | I31: 198 | J31: 0 | K31: =J31*($L$2-1) -> 0 | L31: =SUM(I31:K31) -> 198
A32: 28 | B32: GWDMR028 | C32: PVC Square End Drop 160 mm | D32: =CONCATENATE(C32," (Code: ",B32,")") -> PVC Square End Drop 160 mm (Code: GWDMR028) | E32: each | F32: GWD MR | G32: ARS | H32: ARS Fittings | I32: 222 | J32: 0 | K32: =J32*($L$2-1) -> 0 | L32: =SUM(I32:K32) -> 222
A33: 29 | B33: GWDMR029 | C33: PVC Square Half End Drop 140 mm | D33: =CONCATENATE(C33," (Code: ",B33,")") -> PVC Square Half End Drop 140 mm (Code: GWDMR029) | E33: each | F33: GWD MR | G33: ARS | H33: ARS Fittings | I33: 180 | J33: 0 | K33: =J33*($L$2-1) -> 0 | L33: =SUM(I33:K33) -> 180
A34: 30 | B34: GWDMR030 | C34: PVC Square Half End Drop 160 mm | D34: =CONCATENATE(C34," (Code: ",B34,")") -> PVC Square Half End Drop 160 mm (Code: GWDMR030) | E34: each | F34: GWD MR | G34: ARS | H34: ARS Fittings | I34: 204 | J34: 0 | K34: =J34*($L$2-1) -> 0 | L34: =SUM(I34:K34) -> 204
A35: 31 | B35: GWDMR031 | C35: S&F PVC 45o Elbow 90 mm (DG) | D35: =CONCATENATE(C35," (Code: ",B35,")") -> S&F PVC 45o Elbow 90 mm (DG) (Code: GWDMR031) | E35: each | F35: GWD MR | G35: PVC Fittings | H35: PVC Elbow | I35: 45 | J35: 31.5 | K35: =J35*($L$2-1) -> 0 | L35: =SUM(I35:K35) -> 76.5
A36: 32 | B36: GWDMR032 | C36: S&F PVC 45o Elbow 140 mm (DG) | D36: =CONCATENATE(C36," (Code: ",B36,")") -> S&F PVC 45o Elbow 140 mm (DG) (Code: GWDMR032) | E36: each | F36: GWD MR | G36: PVC Fittings | H36: PVC Elbow | I36: 80 | J36: 38 | K36: =J36*($L$2-1) -> 0 | L36: =SUM(I36:K36) -> 118
... A78: 74 | B78: GWDMR075 | C78: 63 mm dia UPVC pipe | D78: =CONCATENATE(C78," (Code: ",B78,")") -> 63 mm dia UPVC pipe (Code: GWDMR075) | E78: metre | F78: GWD MR | G78: MWSS | H78: Pump Accessories | I78: 552 | J78: 0 | K78: =J78*($L$2-1) -> 0 | L78: =SUM(I78:K78) -> 552
A79: 75 | B79: GWDMR076 | C79: 20 mm dia HDPE pipe (DG) (8kg) | D79: =CONCATENATE(C79," (Code: ",B79,")") -> 20 mm dia HDPE pipe (DG) (8kg) (Code: GWDMR076) | E79: metre | F79: GWD MR | G79: MWSS | H79: Pump Accessories | I79: {=IFERROR(INDEX(DerivedRates,MATCH(B79,DerivedCodes,0), ), )} -> 20 | J79: 0 | K79: =J79*($L$2-1) -> 0 | L79: =SUM(I79:K79) -> 20
A80: 76 | B80: GWDMR077 | C80: 32 mm dia HDPE pipe (DG) (8kg) | D80: =CONCATENATE(C80," (Code: ",B80,")") -> 32 mm dia HDPE pipe (DG) (8kg) (Code: GWDMR077) | E80: metre | F80: GWD MR | G80: MWSS | H80: Pump Accessories | I80: {=IFERROR(INDEX(DerivedRates,MATCH(B80,DerivedCodes,0), ), )} -> 20 | J80: 0 | K80: =J80*($L$2-1) -> 0 | L80: =SUM(I80:K80) -> 20
A81: 77 | B81: GWDMR078 | C81: 40 mm dia HDPE pipe (DG) (8kg) | D81: =CONCATENATE(C81," (Code: ",B81,")") -> 40 mm dia HDPE pipe (DG) (8kg) (Code: GWDMR078) | E81: metre | F81: GWD MR | G81: MWSS | H81: Pump Accessories | I81: {=IFERROR(INDEX(DerivedRates,MATCH(B81,DerivedCodes,0), ), )} -> 29 | J81: 0 | K81: =J81*($L$2-1) -> 0 | L81: =SUM(I81:K81) -> 29
A82: 78 | B82: GWDMR079 | C82: 32 mm SS Adapter | D82: =CONCATENATE(C82," (Code: ",B82,")") -> 32 mm SS Adapter (Code: GWDMR079) | E82: each | F82: GWD MR | G82: MWSS | H82: Pump Accessories | I82: 804 | J82: 0 | K82: =J82*($L$2-1) -> 0 | L82: =SUM(I82:K82) -> 804
A83: 79 | B83: GWDMR080 | C83: 40 mm SS Adapter | D83: =CONCATENATE(C83," (Code: ",B83,")") -> 40 mm SS Adapter (Code: GWDMR080) | E83: each | F83: GWD MR | G83: MWSS | H83: Pump Accessories | I83: 960 | J83: 0 | K83: =J83*($L$2-1) -> 0 | L83: =SUM(I83:K83) -> 960
A84: 80 | B84: GWDMR081 | C84: 50 mm SS Adapter | D84: =CONCATENATE(C84," (Code: ",B84,")") -> 50 mm SS Adapter (Code: GWDMR081) | E84: each | F84: GWD MR | G84: MWSS | H84: Pump Accessories | I84: 1200 | J84: 0 | K84: =J84*($L$2-1) -> 0 | L84: =SUM(I84:K84) -> 1200
A85: 81 | B85: GWDMR082 | C85: 50 mm UPVC Union | D85: =CONCATENATE(C85," (Code: ",B85,")") -> 50 mm UPVC Union (Code: GWDMR082) | E85: each | F85: GWD MR | G85: MWSS | H85: Pump Accessories | I85: 360 | J85: 0 | K85: =J85*($L$2-1) -> 0 | L85: =SUM(I85:K85) -> 360
A86: 82 | B86: GWDMR083 | C86: 63 mm UPVC Union | D86: =CONCATENATE(C86," (Code: ",B86,")") -> 63 mm UPVC Union (Code: GWDMR083) | E86: each | F86: GWD MR | G86: MWSS | H86: Pump Accessories | I86: 540 | J86: 0 | K86: =J86*($L$2-1) -> 0 | L86: =SUM(I86:K86) -> 540
A87: 83 | B87: GWDMR084 | C87: 75 mm UPVC Union | D87: =CONCATENATE(C87," (Code: ",B87,")") -> 75 mm UPVC Union (Code: GWDMR084) | E87: each | F87: GWD MR | G87: MWSS | H87: Pump Accessories | I87: 1200 | J87: 0 | K87: =J87*($L$2-1) -> 0 | L87: =SUM(I87:K87) -> 1200
A88: 84 | B88: GWDMR085 | C88: Sodium Bentonite (ordinary) | D88: =CONCATENATE(C88," (Code: ",B88,")") -> Sodium Bentonite (ordinary) (Code: GWDMR085) | E88: tonne | F88: GWD MR | G88: Tubewell | H88: Tubewell Consumables | I88: 7000 | J88: 0 | K88: =J88*($L$2-1) -> 0 | L88: =SUM(I88:K88) -> 7000
...

Sheet ARS Filter Media
A1: Filter Media for ARS
A2: 0 | B2: Supply and filling of 40mm metal as filter medium
A3: Code | B3: Description | C3: Unit | D3: Quantity | E3: Rate | F3: Amount
B4: Details of cost for 1 cum
B5: MATERIAL:
A6: 293 | B6: Stone Aggregate (Single size) : 40 mm nominal size | C6: m3 | D6: 1 | E6: 1300 | F6: =D6*E6 -> 1300
B7: LABOUR:
A8: 2206 | B8: Carriage of Stone aggregate 40 mm nominal size and above | C8: m3 | D8: 1 | E8: 178.19 | F8: =D8*E8 -> 178.19
A9: 115 | B9: Coolie | C9: Day | D9: 0.4 | E9: 645 | F9: =E9*D9 -> 258
B10: TOTAL | F10: =SUM(F6:F9) -> 1736.19
B11: Add Water Charges @ 1% | F11: =F10*1% -> 17.3619
B12: TOTAL | F12: =SUM(F10:F11) -> 1753.5519
B13: Add CPOH @ 15% | F13: =F12*15% -> 263.03278
B14: TOTAL | F14: =SUM(F12:F13) -> 2016.5847
B15: Cost per 1 cum | F15: =F14 -> 2016.5847
B16: Say | F16: =MROUND(F15, 0.05) -> 2016.6
A17: =CONCATENATE("Say ",F16," x Cost Index") -> Say 2016.6 x Cost Index
A18: 0 | B18: Supply and filling of 25mm metal as filter medium
A19: Code | B19: Description | C19: Unit | D19: Quantity | E19: Rate | F19: Amount
B20: Details of cost for 1 cum
B21: MATERIAL:
A22: 294 | B22: Stone Aggregate (Single size) : 25 mm nominal size | C22: m3 | D22: 1 | E22: 1350 | F22: =D22*E22 -> 1350
B23: LABOUR:
A24: 2202 | B24: Carriage of Stone aggregate below 40 mm nominal size | C24: m3 | D24: 1 | E24: 163.93 | F24: =D24*E24 -> 163.93
A25: 115 | B25: Coolie | C25: Day | D25: 0.4 | E25: 645 | F25: =E25*D25 -> 258
B26: TOTAL | F26: =SUM(F22:F25) -> 1771.93
B27: Add Water Charges @ 1% | F27: =F26*1% -> 17.7193
B28: TOTAL | F28: =SUM(F26:F27) -> 1789.6493
B29: Add CPOH @ 15% | F29: =F28*15% -> 268.44739
B30: TOTAL | F30: =SUM(F28:F29) -> 2058.0967
B31: Cost per 1 cum | F31: =F30 -> 2058.0967
B32: Say | F32: =MROUND(F31, 0.05) -> 2058.1
A33: =CONCATENATE("Say ",F32," x Cost Index") -> Say 2058.1 x Cost Index
A34: 0 | B34: Supply and filling of 20mm/6mm metal as filter medium
A35: Code | B35: Description | C35: Unit | D35: Quantity | E35: Rate | F35: Amount
B36: Details of cost for 1 cum
B37: MATERIAL:
A38: 0295/0298 | B38: Stone Aggregate (Single size) : 20 mm / 6 mm nominal size | C38: m3 | D38: 1 | E38: 1400 | F38: =D38*E38 -> 1400
B39: LABOUR:
A40: 2202 | B40: Carriage of Stone aggregate below 40 mm nominal size | C40: m3 | D40: 1 | E40: 163.93 | F40: =D40*E40 -> 163.93
...

Sheet BW Casing Pipes
A1: Casing Pipe For Borewell , Tube Well And Filterpoint Well
A2: 0 | B2: Supplying, assembling, lowering and fixing in vertical position in Borewell, PVC 140 mm 6 Kg/cm2 well casing pipe of required dia, conforming to IS : 4985:2000, including required hire and labour charges, fittings & accessories etc. all complete, for all depths, as per direction of Engineer- in- Charge.
A3: Code | B3: Description | C3: Unit | D3: Quantity | E3: Rate | F3: Amount
B4: Details of cost for 100 metre
B5: MATERIAL:
A6: MR10215 | B6: PVC Pipe, 6kg/cm2, 140mm Dia | C6: metre | D6: 100 | E6: {=IFERROR(INDEX(LMRRates,MATCH(A6,LMRCodes,0), ), )} -> 281 | F6: =D6*E6 -> 28100
B7: TOTAL | F7: =SUM(F6) -> 28100
B8: Add Water Charges @ 1% | F8: =F7*1/100 -> 281
B9: TOTAL | F9: =SUM(F7:F8) -> 28381
B10: Add CPOH @ 15% | F10: =F9*0.15 -> 4257.15
B11: TOTAL | F11: =SUM(F9:F10) -> 32638.15
B12: Cost of 100 metre | F12: =F11 -> 32638.15
B13: Cost per metre | F13: =MROUND((F12/100), 0.05) -> 326.4
B14: LABOUR:
A15: 2321 | B15: Carriage of Spun iron S & S pipes 150 mm dia | C15: 100 meter | D15: 50 | E15: 597 | F15: =E15/2 -> 298.5
A16: 114 | B16: Beldar | C16: Day | D16: 0.5 | E16: 645 | F16: =E16*D16 -> 322.5
A17: 115 | B17: Coolie | C17: Day | D17: 0.5 | E17: 645 | F17: =E17*D17 -> 322.5
A18: 9999 | B18: Sundries-(Adhesive etc.) | C18: L.S | D18: 10.07 | E18: 2.12 | F18: =E18*D18 -> 21.3484
B19: TOTAL | F19: =SUM(F15:F18) -> 964.8484
B20: Add Water Charges @ 1% | F20: =F19*0.01 -> 9.648484
B21: TOTAL | F21: =SUM(F19:F20) -> 974.49688
B22: Add CPOH @ 15% | F22: =F21*0.15 -> 146.17453
B23: TOTAL | F23: =SUM(F21:F22) -> 1120.6714
B24: Cost of 100.0 metre | F24: =F23 -> 1120.6714
B25: Cost per metre | F25: =F24/100 -> 11.206714
B26: Say | F26: =MROUND(F25, 0.05) -> 11.2
A27: =CONCATENATE("Say ",F13," + ",F26," x Cost Index") -> Say 326.4 + 11.2 x Cost Index
A28: 0 | B28: Supplying, assembling, lowering and fixing in vertical position in Borewell, PVC 140 mm 8 Kg/cm2 well casing pipe of required dia, conforming to IS : 4985:2000, including required hire and labour charges, fittings & accessories etc. all complete, for all depths, as per direction of Engineer- in- Charge.
A29: Code | B29: Description | C29: Unit | D29: Quantity | E29: Rate | F29: Amount
B30: Details of cost for 100 metre
B31: MATERIAL:
A32: MR10225 | B32: PVC Pipe, 8kg/cm2, 140mm Dia. | C32: metre | D32: 100 | E32: {=IFERROR(INDEX(LMRRates,MATCH(A32,LMRCodes,0), ), )} -> 398 | F32: =D32*E32 -> 39800
B33: TOTAL | F33: =SUM(F32) -> 39800
B34: Add Water Charges @ 1% | F34: =F33*0.01 -> 398
B35: TOTAL | F35: =SUM(F33:F34) -> 40198
B36: Add CPOH @ 15% | F36: =F35*0.15 -> 6029.7
B37: TOTAL | F37: =SUM(F35:F36) -> 46227.7
B38: Cost of 100 metre | F38: =F37 -> 46227.7
B39: Cost per metre | F39: =MROUND((F38/100), 0.05) -> 462.3
B40: LABOUR:
...

Sheet BW Casing Pipe Erection Charge
A1: Casing Pipe For Borewell , Tube Well And Filterpoint Well
A2: 0 | B2: Assembling, lowering and fixing in vertical position in Borewell, PVC 140 mm 6 Kg/cm2 well casing pipe of required dia, conforming to IS : 4985:2000, including required hire and labour charges, fittings & accessories etc. all complete, for all depths, as per direction of Engineer- in- Charge. (Excluding Material)
A3: Code | B3: Description | C3: Unit | D3: Quantity | E3: Rate | F3: Amount
B4: Details of cost for 100 metre
B5: LABOUR:
A6: 2321 | B6: Carriage of Spun iron S & S pipes 150 mm dia | C6: 100 meter | D6: 50 | E6: 597 | F6: =E6/2 -> 298.5
A7: 114 | B7: Beldar | C7: Day | D7: 0.5 | E7: 645 | F7: =E7*D7 -> 322.5
A8: 115 | B8: Coolie | C8: Day | D8: 0.5 | E8: 645 | F8: =E8*D8 -> 322.5
A9: 9999 | B9: Sundries-(Adhesive etc.) | C9: L.S | D9: 10.07 | E9: 2.12 | F9: =E9*D9 -> 21.3484
B10: TOTAL | F10: =SUM(F6:F9) -> 964.8484
B11: Add Water Charges @ 1% | F11: =F10*0.01 -> 9.648484
B12: TOTAL | F12: =SUM(F10:F11) -> 974.49688
B13: Add CPOH @ 15% | F13: =F12*0.15 -> 146.17453
B14: TOTAL | F14: =SUM(F12:F13) -> 1120.6714
B15: Cost of 100.0 metre | F15: =F14 -> 1120.6714
B16: Cost per metre | F16: =F15/100 -> 11.206714
B17: Say | F17: =MROUND(F16, 0.05) -> 11.2
A18: =CONCATENATE("Say ",F17," x Cost Index") -> Say 11.2 x Cost Index

Sheet Electrical Essentials
A1: Spec Code | B1: Specification | C1: Rate (₹) | D1: Unit
A2: 2.10.1 | B2: Supplying and fixing 5 amps to 32 amps rating, 240/415 volts, "C" curve, miniature circuit breaker suitable for inductive load of following poles in the existing MCB DB complete with connections, testing and commissioning etc. as required. Single pole (2.10.1) | C2: 193.76 | D2: each
A3: 2.10.2 | B3: Supplying and fixing 5 amps to 32 amps rating, 240/415 volts, "C" curve, miniature circuit breaker suitable for inductive load of following poles in the existing MCB DB complete with connections, testing and commissioning etc. as required. Single pole and netural (2.10.2) | C3: 452.76 | D3: each
A4: 2.10.3 | B4: Supplying and fixing 5 amps to 32 amps rating, 240/415 volts, "C" curve, miniature circuit breaker suitable for inductive load of following poles in the existing MCB DB complete with connections, testing and commissioning etc. as required. Double pole (2.10.3) | C4: 495.76 | D4: each
A5: 2.10.4 | B5: Supplying and fixing 5 amps to 32 amps rating, 240/415 volts, "C" curve, miniature circuit breaker suitable for inductive load of following poles in the existing MCB DB complete with connections, testing and commissioning etc. as required. Triple pole (2.10.4) | C5: 760.76 | D5: each
A6: 2.10.5 | B6: Supplying and fixing 5 amps to 32 amps rating, 240/415 volts, "C" curve, miniature circuit breaker suitable for inductive load of following poles in the existing MCB DB complete with connections, testing and commissioning etc. as required. Triple pole and neutral (2.10.5) | C6: 927.76 | D6: each
A7: 2.3.1 | B7: Supplying and fixing following way, single pole and neutral, sheet steel, MCB distribution board, 240 V, on surface/ recess, complete with tinned copper bus bar, neutral bus bar, earth bar, din bar, interconnections, powder painted including earthing etc. as required. (But without MCBIRCCB/Isolator 6 way, Double door (2.3.1) | C7: 1668.16 | D7: each
A8: 2.3.2 | B8: Supplying and fixing following way, single pole and neutral, sheet steel, MCB distribution board, 240 V, on surface/ recess, complete with tinned copper bus bar, neutral bus bar, earth bar, din bar, interconnections, powder painted including earthing etc. as required. (But without MCBIRCCB/Isolator 8 way, Double door (2.3.2) | C8: 1945.16 | D8: each
A9: 2.3.3 | B9: Supplying and fixing following way, single pole and neutral, sheet steel, MCB distribution board, 240 V, on surface/ recess, complete with tinned copper bus bar, neutral bus bar, earth bar, din bar, interconnections, powder painted including earthing etc. as required. (But without MCBIRCCB/Isolator 12 way, Double door (2.3.3) | C9: 1750.16 | D9: each
A10: 2.3.4 | B10: Supplying and fixing following way, single pole and neutral, sheet steel, MCB distribution board, 240 V, on surface/ recess, complete with tinned copper bus bar, neutral bus bar, earth bar, din bar, interconnections, powder painted including earthing etc. as required. (But without MCBIRCCB/Isolator 16 way, Double door (2.3.4) | C10: 2374.16 | D10: each
A11: 2.14.1 | B11: Supplying and fixing following rating, double pole, (single phase and neutral), 240 volts, residual current circuit breaker (RCCB), having a sensitivity current upto 300 milliamperes in the existing MCB DB complete with connections, testing and commissioning etc. as required. 25 amps (2.14.1) | C11: 1531.45 | D11: each
A12: 2.14.2 | B12: Supplying and fixing following rating, double pole, (single phase and neutral), 240 volts, residual current circuit breaker (RCCB), having a sensitivity current upto 300 milliamperes in the existing MCB DB complete with connections, testing and commissioning etc. as required. 40 amps (2.14.2) | C12: 1995.45 | D12: each
A13: 2.14.3 | B13: Supplying and fixing following rating, double pole, (single phase and neutral), 240 volts, residual current circuit breaker (RCCB), having a sensitivity current upto 300 milliamperes in the existing MCB DB complete with connections, testing and commissioning etc. as required. 63 amps (2.14.3) | C13: 2055.45 | D13: each
... A53: 1.17.37 | B53: Supplying and drawing following sizes of FRLS PVC insulated copper conductor, single core cable in the existing surface / recessed steel/ PVC conduit as required.10 x 6 sq. mm(1.17.37) | C53: 730.69 | D53: metre

Sheet GI on Wall PRICE
A1: Spec Code | B1: Specification | C1: Rate (₹) | D1: Unit
A2: 18.10.1 | B2: Providing and fixing G.I. pipes complete with G.I. fittings and clamps, including cutting and making good the walls etc. Internal work- Exposed on wall 15 mm dia nominal bore (18.10.1) | C2: 264.02 | D2: meter
A3: 18.10.2 | B3: Providing and fixing G.I. pipes complete with G.I. fittings and clamps, including cutting and making good the walls etc. Internal work- Exposed on wall 20 mm dia nominal bore (18.10.2) | C3: 324.12 | D3: meter
A4: 18.10.3 | B4: Providing and fixing G.I. pipes complete with G.I. fittings and clamps, including cutting and making good the walls etc. Internal work- Exposed on wall 25 mm dia nominal bore (18.10.3) | C4: 426.41 | D4: meter
A5: 18.10.4 | B5: Providing and fixing G.I. pipes complete with G.I. fittings and clamps, including cutting and making good the walls etc. Internal work- Exposed on wall 32 mm dia nominal bore (18.10.4) | C5: 489.26 | D5: meter
A6: 18.10.5 | B6: Providing and fixing G.I. pipes complete with G.I. fittings and clamps, including cutting and making good the walls etc. Internal work- Exposed on wall 40 mm dia nominal bore (18.10.5) | C6: 629.54 | D6: meter
A7: 18.10.6 | B7: Providing and fixing G.I. pipes complete with G.I. fittings and clamps, including cutting and making good the walls etc. Internal work- Exposed on wall 50 mm dia nominal bore (18.10.6) | C7: 775.43 | D7: meter

Sheet GI wo Trench
A1: GI Pipe Without Trenching
A2: 0 | B2: Providing and fixing G.I. pipes complete with G.I fittings: 25 mm dia nominal bore
A3: Code | B3: Description | C3: Unit | D3: Quantity | E3: Rate | F3: Amount
B4: Details of cost for 10 metre
B5: MATERIAL:
A6: 1547 | B6: G.I. pipes 25 mm dia | C6: metre | D6: 10.2 | E6: 196 | F6: =D6*E6 -> 1999.2
B7: Weight for carriage = pipe weight + 2% for fittings =
B8: 1.02 x 24.60 = 25.092 kg = 0.025092 tonne
A9: 2271 | B9: Carriage of G.I. pipes below 100 mm dia | C9: tonne | D9: 0.02509 | E9: 145.72 | F9: =D9*E9 -> 3.6561148
A10: 9999 | B10: Sundries-White lead, hemp, oil etc | C10: L.S | D10: 6.76 | E10: 2.12 | F10: =D10*E10 -> 14.3312
B11: LABOUR:
A12: 116 | B12: Fitter(grade1) | C12: Day | D12: 0.12 | E12: 784 | F12: =D12*E12 -> 94.08
A13: 114 | B13: Beldar | C13: Day | D13: 0.25 | E13: 645 | F13: =D13*E13 -> 161.25
B14: TOTAL | F14: =SUM(F6:F13) -> 2272.5173
B15: Add Water Charges @ 1% | F15: =F14*0.01 -> 22.725173
B16: TOTAL | F16: =SUM(F14:F15) -> 2295.2425
B17: Add CPOH @ 15% | F17: =F16*0.15 -> 344.28637
B18: TOTAL | F18: =SUM(F16:F17) -> 2639.5289
B19: Cost of 10.0 metre | F19: =F18 -> 2639.5289
B20: Cost per metre | F20: =F19/10 -> 263.95289
B21: Say | F21: =MROUND(F20, 0.05) -> 263.95
A22: 0 | B22: Providing and fixing G.I. pipes complete with G.I fittings: 32 mm dia nominal bore
A23: Code | B23: Description | C23: Unit | D23: Quantity | E23: Rate | F23: Amount
B24: Details of cost for 10 metre
B25: MATERIAL:
A26: 1548 | B26: G.I. pipes 32 mm dia | C26: metre | D26: 10.2 | E26: 225 | F26: =10.2*225 -> 2295
B27: Weight for carriage = pipe weight + 2% for fittings =
B28: 1.02 x 31.70 = 32.334 kg = 0.032334 tonne
A29: 2271 | B29: Carriage of G.I. pipes below 100 mm dia | C29: tonne | D29: 0.03233 | E29: 145.72 | F29: =D29*E29 -> 4.7111276
A30: 9999 | B30: Sundries-White lead, hemp, oil etc. | C30: L.S | D30: 6.76 | E30: 2.12 | F30: =D30*E30 -> 14.3312
B31: LABOUR:
A32: 116 | B32: Fitter(grade1) | C32: Day | D32: 0.12 | E32: 784 | F32: =D32*E32 -> 94.08
A33: 114 | B33: Beldar | C33: Day | D33: 0.25 | E33: 645 | F33: =D33*E33 -> 161.25
B34: TOTAL | F34: =SUM(F26:F33) -> 2569.3723
B35: Add Water Charges @ 1% | F35: =F34*0.01 -> 25.693723
B36: TOTAL | F36: =SUM(F34:F35) -> 2595.0661
B37: Add CPOH @ 15% | F37: =F36*0.15 -> 389.25991
B38: TOTAL | F38: =SUM(F36:F37) -> 2984.326
B39: Cost of 10.0 metre | F39: =F38 -> 2984.326
B40: Cost per metre | F40: =F39/10 -> 298.4326
...

Sheet GI With Trench PRICE
A1: Spec Code | B1: Specification | C1: Rate (₹) | D1: Unit
A2: 18.12.1 | B2: Providing and fixing G.I. pipes complete with G.I fittings including trenching and refilling etc. External work 15 mm dia nominal bore (18.12.1) | C2: 232.24 | D2: meter
A3: 18.12.2 | B3: Providing and fixing G.I. pipes complete with G.I fittings including trenching and refilling etc. External work 20 mm dia nominal bore (18.12.2) | C3: 273.77 | D3: meter
A4: 18.12.3 | B4: Providing and fixing G.I. pipes complete with G.I fittings including trenching and refilling etc. External work 25 mm dia nominal bore (18.12.3) | C4: 362.84 | D4: meter
A5: 18.12.4 | B5: Providing and fixing G.I. pipes complete with G.I fittings including trenching and refilling etc. External work 32 mm dia nominal bore (18.12.4) | C5: 397.33 | D5: meter
A6: 18.12.5 | B6: Providing and fixing G.I. pipes complete with G.I fittings including trenching and refilling etc. External work 40 mm dia nominal bore (18.12.5) | C6: 484.72 | D6: meter
A7: 18.12.6 | B7: Providing and fixing G.I. pipes complete with G.I fittings including trenching and refilling etc. External work 50 mm dia nominal bore (18.12.6) | C7: 567.92 | D7: meter
A8: 18.12.7 | B8: Providing and fixing G.I. pipes complete with G.I fittings including trenching and refilling etc. External work 65 mm dia nominal bore (18.12.7) | C8: 667.24 | D8: meter
A9: 18.12.8 | B9: Providing and fixing G.I. pipes complete with G.I fittings including trenching and refilling etc. External work 80 mm dia nominal bore (18.12.8) | C9: 797.9 | D9: meter

Sheet GI Works
A1: Sor/Spec Code | B1: MR Code | C1: Description | F1: Remarks
C2: Unit | D2: Quantity | E2: Rate (₹) | F2: Amount | G2: Label
A3: GI work in single section, fixed with or without connecting plate, including cutting, hoisting, fixing in position and applying a priming coat of approved steel primer all complete.
B4: Header Unit | C4: kilogram | D4: Header Quantity | E4: 100
A5: Header Details | B5: Details of cost for one quintal
A6: Material | G6: M
A7: 8019 | C7: GI sheet: 1.00q Add wastage @ 5% = 0.05q Total+ 1.05q GI sheet 0.8 mm thick confirming to IS 277:1992
C8: q | D8: 1.05 | E8: 9000 | F8: =D8*E8 -> 9450 | G8: M1
A9: Carriage | G9: C
A10: 2205 | C10: Carriage of Steel
C11: tonne | D11: 0.105 | E11: 145.72 | F11: =D11*E11 -> 15.3006 | G11: C1
A12: Labour | G12: L
A13: 116 | C13: Fitter(grade1)
C14: Day | D14: 0.5 | E14: 784 | F14: =E14*D14 -> 392 | G14: L1
A15: 102 | C15: Blacksmith 1st class
C16: Day | D16: 0.75 | E16: 784 | F16: =E16*D16 -> 588 | G16: L2
A17: 103 | C17: Blacksmith 2nd class
C18: Day | D18: 1 | E18: 714 | F18: =E18*D18 -> 714 | G18: L2
A19: 1214/1215 | C19: Welding by electric/gas plant
C20: cm | D20: 850 | E20: 2 | F20: =D20*E20 -> 1700 | G20: L3
A21: Subdata | G21: L
A22: 13.50.3 | C22: Finishing : With ready mixed red oxide zinc chromate primer of approved brand and manufacture on steel galvanised iron /steel works
C23: sqm | D23: 3 | E23: 48.19 | F23: =D23*E23 -> 144.57 | G23: S1
A24: TOTAL | D24: 100 | E24: kilogram | F24: =SUM(F8,F11,F14,F16,F18,F20+F23) -> 13003.871
A25: UNIT TOTAL | D25: 1 | E25: kilogram | F25: =F24/100 -> 130.03871
A26: Water Charge@ 1.00 % | E26: =F25 -> 130.03871 | F26: =E26/100 -> 1.3003871
A27: TOTAL | F27: =F25+F26 -> 131.33909
A28: Contractors Profit & Overhead@ 15.00 % | E28: =F27 -> 131.33909 | F28: =E28*0.15 -> 19.700864
A29: TOTAL | F29: =F27+F28 -> 151.03996
A30: Grand Total | F30: =round(F29,2) -> 151.04 | G30: /kg

Sheet Gravel for TWC
A1: Sor/Spec Code | B1: MR Code | C1: Description | F1: Remarks
C2: Unit | D2: Quantity | E2: Rate (₹) | F2: Amount | G2: Label
A3: Supplying of 4.75 to 8mm size pebble (pebbles shall be hard, clean, free from clay, dust and other impurities), stacking in standard heaps for measurement including cost, conveyance up to 5km and labour charges for stacking, spreading, testing and as per the directions of the department officers etc complete and as per CPHEEO specification.
B4: Header Unit | C4: cum | D4: Header Quantity | E4: 1
A5: Header Details | B5: Details of cost for 1 cum
A6: Material | G6: M
B7: MR10044 | C7: Cost of pebble 2 mm to 6 mm / 6mm to 12mm.
C8: cum | D8: 1 | E8: {=IFERROR(INDEX(LMRRates,MATCH(B7,LMRCodes,0), ), )} -> 6553 | F8: =D8*E8 -> 6553 | G8: M1
A9: TOTAL | D9: 1 | E9: cum | F9: =F8 -> 6553
A10: UNIT TOTAL | D10: 1 | E10: cum | F10: =F9/D9 -> 6553
A11: Water Charge@ 1.00 % | E11: =F10 -> 6553 | F11: =E11*1% -> 65.53
A12: TOTAL | F12: =F10+F11 -> 6618.53
A13: Contractors Profit & Overhead@ 15.00 % | E13: =F12 -> 6618.53 | F13: =E13*15% -> 992.7795
A14: TOTAL | F14: =round(F12+F13,2) -> 7611.31
A15: Carriage | G15: C
A16: 2202 | C16: Carriage of Stone aggregate below 40 mm nominal size
C17: cum | D17: 1 | E17: 163.93 | F17: =D17*E17 -> 163.93 | G17: C1
A18: Labour | G18: L
A19: 115 | C19: Coolie For spreading.
C20: Day | D20: 0.8 | E20: 645 | F20: =D20*E20 -> 516 | G20: L1
A21: Tools & Plants | G21: L
A22: 9999 | C22: Sundries Hire for tools.
C23: L.S | D23: 10 | E23: 2.12 | F23: =D23*E23 -> 21.2 | G23: T1
A24: 9999 | C24: Sundries Charges for testing.
C25: L.S | D25: 5 | E25: 2.12 | F25: =D25*E25 -> 10.6 | G25: T2
A26: TOTAL | D26: 1 | E26: cum | F26: =F17+F20+F23+F25 -> 711.73
A27: UNIT TOTAL | D27: 1 | E27: cum | F27: =F26/D26 -> 711.73
A28: Water Charge@ 1.00 % | E28: =F27 -> 711.73 | F28: =E28*1% -> 7.1173
A29: TOTAL | F29: =F27+F28 -> 718.8473
A30: Contractors Profit & Overhead@ 15.00 % | E30: =F29 -> 718.8473 | F30: =E30*15% -> 107.82709
A31: TOTAL | F31: =round(F29+F30,2) -> 826.67
A32: =CONCATENATE("Say ₹ ",F14," + ",F31," x Cost Index") -> Say ₹ 7611.31 + 826.67 x Cost Index | H32: =F8*1.01*1.15 -> 7611.3095 | I32: =(F17+F20+F23+F25)*1.01*1.15 -> 826.6744

Sheet Gutter&Clamp
A1: Gutter & Clamp
A2: 0 | B2: Providing and fixing PVC full pipe as gutter pipes includes laying jointing of pipes complete as per direction of Engineer in Charge for 140 mm dia 6 KGF/cm2
A3: Code | B3: Description | C3: Unit | D3: Quantity | E3: Rate | F3: Amount
B4: Details of cost for 10 metre
B5: MATERIALS:
A6: MR10215 | B6: PVC Pipe, 6kg/cm2, 140mm Dia | C6: metre | D6: 10.5 | E6: {=IFERROR(INDEX(LMRRates,MATCH(A6,LMRCodes,0), ), )} -> 281 | F6: =D6*E6 -> 2950.5
B7: Add 5% for fittings and wastage etc. on (A)
B8: Total | F8: =SUM(F6:F7) -> 2950.5
B9: Add Water Charges @ 1% | F9: =F8*0.01 -> 29.505
B10: TOTAL | F10: =F8+F9 -> 2980.005
B11: Add CPOH @ 15% | F11: =F10*0.15 -> 447.00075
B12: TOTAL | F12: =F10+F11 -> 3427.0057
B13: Cost of 10.0 metre | F13: =F12 -> 3427.0057
B14: Cost per metre | F14: =round((F13/10),2) -> 342.7
A15: 116 | B15: Fitter(grade1) | C15: Day | D15: 0.33 | E15: 784 | F15: =D15*E15 -> 258.72
A16: 117 | B16: Assistant Fitter or 2nd class fitter | C16: Day | D16: 0.4 | E16: 714 | F16: =D16*E16 -> 285.6
A17: 114 | B17: Beldar | C17: Day | D17: 0.4 | E17: 645 | F17: =D17*E17 -> 258
B18: TOTAL | F18: =SUM(F15:F17) -> 802.32
B19: Add Water Charges @ 1% | F19: =F18*0.01 -> 8.0232
B20: TOTAL | F20: =SUM(F18:F19) -> 810.3432
B21: Add CPOH @ 15% | F21: =F20*0.15 -> 121.55148
B22: TOTAL | F22: =SUM(F20:F21) -> 931.89468
B23: Cost of 10.0 metre | F23: =F22 -> 931.89468
B24: Cost per metre | F24: =round((F23/10),2) -> 93.19
A25: =CONCATENATE("Say ₹ ",F14," + ",F24," x Cost Index") -> Say ₹ 342.7 + 93.19 x Cost Index
A26: 0 | B26: Providing and fixing PVC gutter pipes includes laying jointing of pipes, complete as per direction of Engineer in Charge.for 160 mm dia 6 KGF/cm2
A27: Code | B27: Description | C27: Unit | D27: Quantity | E27: Rate | F27: Amount
B28: Details of cost for 10 metre
B29: MATERIALS:
A30: MR10216 | B30: PVC Pipe, 6kg/cm2, 160mm Dia | C30: metre | D30: 10.5 | E30: {=IFERROR(INDEX(LMRRates,MATCH(A30,LMRCodes,0), ), )} -> 387 | F30: =D30*E30 -> 4063.5
B31: Add 5% for fittings and wastage etc. on (A)
B32: Total | F32: =SUM(F30:F31) -> 4063.5
B33: Add Water Charges @ 1% | F33: =F32*0.01 -> 40.635
